2019-10-15 16:35:32,924 ERROR: Exception on / [GET] [in /home/orillion/CODING/HTBAH_Character_Creator/venv/lib/python3.7/site-packages/flask/app.py:1891]
Traceback (most recent call last):
  File "/home/orillion/CODING/HTBAH_Character_Creator/venv/lib/python3.7/site-packages/sqlalchemy/engine/base.py", line 1249, in _execute_context
    cursor, statement, parameters, context
  File "/home/orillion/CODING/HTBAH_Character_Creator/venv/lib/python3.7/site-packages/sqlalchemy/engine/default.py", line 580, in do_execute
    cursor.execute(statement, parameters)
sqlite3.OperationalError: no such table: event

The above exception was the direct cause of the following exception:

Traceback (most recent call last):
  File "/home/orillion/CODING/HTBAH_Character_Creator/venv/lib/python3.7/site-packages/flask/app.py", line 2446, in wsgi_app
    response = self.full_dispatch_request()
  File "/home/orillion/CODING/HTBAH_Character_Creator/venv/lib/python3.7/site-packages/flask/app.py", line 1951, in full_dispatch_request
    rv = self.handle_user_exception(e)
  File "/home/orillion/CODING/HTBAH_Character_Creator/venv/lib/python3.7/site-packages/flask/app.py", line 1820, in handle_user_exception
    reraise(exc_type, exc_value, tb)
  File "/home/orillion/CODING/HTBAH_Character_Creator/venv/lib/python3.7/site-packages/flask/_compat.py", line 39, in reraise
    raise value
  File "/home/orillion/CODING/HTBAH_Character_Creator/venv/lib/python3.7/site-packages/flask/app.py", line 1949, in full_dispatch_request
    rv = self.dispatch_request()
  File "/home/orillion/CODING/HTBAH_Character_Creator/venv/lib/python3.7/site-packages/flask/app.py", line 1935, in dispatch_request
    return self.view_functions[rule.endpoint](**req.view_args)
  File "/home/orillion/CODING/HTBAH_Character_Creator/app/main/routes.py", line 42, in index
    events = db.session.query(db_event).all()
  File "/home/orillion/CODING/HTBAH_Character_Creator/venv/lib/python3.7/site-packages/sqlalchemy/orm/query.py", line 3186, in all
    return list(self)
  File "/home/orillion/CODING/HTBAH_Character_Creator/venv/lib/python3.7/site-packages/sqlalchemy/orm/query.py", line 3342, in __iter__
    return self._execute_and_instances(context)
  File "/home/orillion/CODING/HTBAH_Character_Creator/venv/lib/python3.7/site-packages/sqlalchemy/orm/query.py", line 3367, in _execute_and_instances
    result = conn.execute(querycontext.statement, self._params)
  File "/home/orillion/CODING/HTBAH_Character_Creator/venv/lib/python3.7/site-packages/sqlalchemy/engine/base.py", line 988, in execute
    return meth(self, multiparams, params)
  File "/home/orillion/CODING/HTBAH_Character_Creator/venv/lib/python3.7/site-packages/sqlalchemy/sql/elements.py", line 287, in _execute_on_connection
    return connection._execute_clauseelement(self, multiparams, params)
  File "/home/orillion/CODING/HTBAH_Character_Creator/venv/lib/python3.7/site-packages/sqlalchemy/engine/base.py", line 1107, in _execute_clauseelement
    distilled_params,
  File "/home/orillion/CODING/HTBAH_Character_Creator/venv/lib/python3.7/site-packages/sqlalchemy/engine/base.py", line 1253, in _execute_context
    e, statement, parameters, cursor, context
  File "/home/orillion/CODING/HTBAH_Character_Creator/venv/lib/python3.7/site-packages/sqlalchemy/engine/base.py", line 1473, in _handle_dbapi_exception
    util.raise_from_cause(sqlalchemy_exception, exc_info)
  File "/home/orillion/CODING/HTBAH_Character_Creator/venv/lib/python3.7/site-packages/sqlalchemy/util/compat.py", line 398, in raise_from_cause
    reraise(type(exception), exception, tb=exc_tb, cause=cause)
  File "/home/orillion/CODING/HTBAH_Character_Creator/venv/lib/python3.7/site-packages/sqlalchemy/util/compat.py", line 152, in reraise
    raise value.with_traceback(tb)
  File "/home/orillion/CODING/HTBAH_Character_Creator/venv/lib/python3.7/site-packages/sqlalchemy/engine/base.py", line 1249, in _execute_context
    cursor, statement, parameters, context
  File "/home/orillion/CODING/HTBAH_Character_Creator/venv/lib/python3.7/site-packages/sqlalchemy/engine/default.py", line 580, in do_execute
    cursor.execute(statement, parameters)
sqlalchemy.exc.OperationalError: (sqlite3.OperationalError) no such table: event
[SQL: SELECT event.id AS event_id, event.name AS event_name, event.type AS event_type, event.event_comment AS event_event_comment, event.event_image AS event_event_image, event.main_text AS event_main_text, event.sub_text AS event_sub_text, event.location AS event_location, event.dateofevent AS event_dateofevent, event.max_player AS event_max_player, event.max_games AS event_max_games, event.event_host AS event_event_host 
FROM event]
(Background on this error at: http://sqlalche.me/e/e3q8)
