2019-10-17 13:32:02,219 ERROR: Exception on /creator/index [GET] [in /Library/Python/3.7/site-packages/flask/app.py:1891]
Traceback (most recent call last):
  File "/Library/Python/3.7/site-packages/sqlalchemy/orm/relationships.py", line 2361, in _determine_joins
    consider_as_foreign_keys=consider_as_foreign_keys,
  File "<string>", line 2, in join_condition
  File "<string>", line 2, in _join_condition
  File "/Library/Python/3.7/site-packages/sqlalchemy/util/deprecations.py", line 128, in warned
    return fn(*args, **kwargs)
  File "/Library/Python/3.7/site-packages/sqlalchemy/sql/selectable.py", line 947, in _join_condition
    % (a.description, b.description, hint)
sqlalchemy.exc.NoForeignKeysError: Can't find any foreign key relationships between 'Collection' and 'Charactersheet'.

During handling of the above exception, another exception occurred:

Traceback (most recent call last):
  File "/Library/Python/3.7/site-packages/flask/app.py", line 2446, in wsgi_app
    response = self.full_dispatch_request()
  File "/Library/Python/3.7/site-packages/flask/app.py", line 1951, in full_dispatch_request
    rv = self.handle_user_exception(e)
  File "/Library/Python/3.7/site-packages/flask/app.py", line 1820, in handle_user_exception
    reraise(exc_type, exc_value, tb)
  File "/Library/Python/3.7/site-packages/flask/_compat.py", line 39, in reraise
    raise value
  File "/Library/Python/3.7/site-packages/flask/app.py", line 1949, in full_dispatch_request
    rv = self.dispatch_request()
  File "/Library/Python/3.7/site-packages/flask/app.py", line 1935, in dispatch_request
    return self.view_functions[rule.endpoint](**req.view_args)
  File "/Users/haikodidzoleit/CODING/HTBAH_creator/app/creator/routes.py", line 13, in creator_index
    collection = db.session.query(Collection).limit(5).all()
  File "/Library/Python/3.7/site-packages/sqlalchemy/orm/scoping.py", line 162, in do
    return getattr(self.registry(), name)(*args, **kwargs)
  File "/Library/Python/3.7/site-packages/sqlalchemy/orm/session.py", line 1544, in query
    return self._query_cls(entities, self, **kwargs)
  File "/Library/Python/3.7/site-packages/sqlalchemy/orm/query.py", line 168, in __init__
    self._set_entities(entities)
  File "/Library/Python/3.7/site-packages/sqlalchemy/orm/query.py", line 200, in _set_entities
    self._set_entity_selectables(self._entities)
  File "/Library/Python/3.7/site-packages/sqlalchemy/orm/query.py", line 231, in _set_entity_selectables
    ent.setup_entity(*d[entity])
  File "/Library/Python/3.7/site-packages/sqlalchemy/orm/query.py", line 4121, in setup_entity
    self._with_polymorphic = ext_info.with_polymorphic_mappers
  File "/Library/Python/3.7/site-packages/sqlalchemy/util/langhelpers.py", line 855, in __get__
    obj.__dict__[self.__name__] = result = self.fget(obj)
  File "/Library/Python/3.7/site-packages/sqlalchemy/orm/mapper.py", line 2135, in _with_polymorphic_mappers
    configure_mappers()
  File "/Library/Python/3.7/site-packages/sqlalchemy/orm/mapper.py", line 3248, in configure_mappers
    mapper._post_configure_properties()
  File "/Library/Python/3.7/site-packages/sqlalchemy/orm/mapper.py", line 1947, in _post_configure_properties
    prop.init()
  File "/Library/Python/3.7/site-packages/sqlalchemy/orm/interfaces.py", line 196, in init
    self.do_init()
  File "/Library/Python/3.7/site-packages/sqlalchemy/orm/relationships.py", line 1861, in do_init
    self._setup_join_conditions()
  File "/Library/Python/3.7/site-packages/sqlalchemy/orm/relationships.py", line 1941, in _setup_join_conditions
    can_be_synced_fn=self._columns_are_mapped,
  File "/Library/Python/3.7/site-packages/sqlalchemy/orm/relationships.py", line 2246, in __init__
    self._determine_joins()
  File "/Library/Python/3.7/site-packages/sqlalchemy/orm/relationships.py", line 2383, in _determine_joins
    "specify a 'primaryjoin' expression." % self.prop
sqlalchemy.exc.NoForeignKeysError: Could not determine join condition between parent/child tables on relationship Collection.chars - there are no foreign keys linking these tables.  Ensure that referencing columns are associated with a ForeignKey or ForeignKeyConstraint, or specify a 'primaryjoin' expression.
2019-10-17 13:35:46,481 ERROR: Exception on /creator/index [GET] [in /Library/Python/3.7/site-packages/flask/app.py:1891]
Traceback (most recent call last):
  File "/Library/Python/3.7/site-packages/flask/app.py", line 2446, in wsgi_app
    response = self.full_dispatch_request()
  File "/Library/Python/3.7/site-packages/flask/app.py", line 1951, in full_dispatch_request
    rv = self.handle_user_exception(e)
  File "/Library/Python/3.7/site-packages/flask/app.py", line 1820, in handle_user_exception
    reraise(exc_type, exc_value, tb)
  File "/Library/Python/3.7/site-packages/flask/_compat.py", line 39, in reraise
    raise value
  File "/Library/Python/3.7/site-packages/flask/app.py", line 1949, in full_dispatch_request
    rv = self.dispatch_request()
  File "/Library/Python/3.7/site-packages/flask/app.py", line 1935, in dispatch_request
    return self.view_functions[rule.endpoint](**req.view_args)
  File "/Users/haikodidzoleit/CODING/HTBAH_creator/app/creator/routes.py", line 13, in creator_index
    collection = db.session.query(Collection).limit(5).all()
  File "/Library/Python/3.7/site-packages/sqlalchemy/orm/scoping.py", line 162, in do
    return getattr(self.registry(), name)(*args, **kwargs)
  File "/Library/Python/3.7/site-packages/sqlalchemy/orm/session.py", line 1544, in query
    return self._query_cls(entities, self, **kwargs)
  File "/Library/Python/3.7/site-packages/sqlalchemy/orm/query.py", line 168, in __init__
    self._set_entities(entities)
  File "/Library/Python/3.7/site-packages/sqlalchemy/orm/query.py", line 200, in _set_entities
    self._set_entity_selectables(self._entities)
  File "/Library/Python/3.7/site-packages/sqlalchemy/orm/query.py", line 231, in _set_entity_selectables
    ent.setup_entity(*d[entity])
  File "/Library/Python/3.7/site-packages/sqlalchemy/orm/query.py", line 4121, in setup_entity
    self._with_polymorphic = ext_info.with_polymorphic_mappers
  File "/Library/Python/3.7/site-packages/sqlalchemy/util/langhelpers.py", line 855, in __get__
    obj.__dict__[self.__name__] = result = self.fget(obj)
  File "/Library/Python/3.7/site-packages/sqlalchemy/orm/mapper.py", line 2135, in _with_polymorphic_mappers
    configure_mappers()
  File "/Library/Python/3.7/site-packages/sqlalchemy/orm/mapper.py", line 3244, in configure_mappers
    raise e
sqlalchemy.exc.InvalidRequestError: One or more mappers failed to initialize - can't proceed with initialization of other mappers. Triggering mapper: 'mapped class Collection->Collection'. Original exception was: Could not determine join condition between parent/child tables on relationship Collection.chars - there are no foreign keys linking these tables.  Ensure that referencing columns are associated with a ForeignKey or ForeignKeyConstraint, or specify a 'primaryjoin' expression.
2019-10-17 13:37:01,393 INFO: Microblog startup [in /Users/haikodidzoleit/CODING/HTBAH_creator/app/__init__.py:84]
2019-10-17 13:37:07,186 INFO: Microblog startup [in /Users/haikodidzoleit/CODING/HTBAH_creator/app/__init__.py:84]
2019-10-17 13:37:17,244 INFO: Microblog startup [in /Users/haikodidzoleit/CODING/HTBAH_creator/app/__init__.py:84]
