2019-10-15 17:59:19,930 ERROR: Exception on / [GET] [in /usr/lib/python3/dist-packages/flask/app.py:1761]
Traceback (most recent call last):
  File "/usr/lib/python3/dist-packages/flask/app.py", line 2292, in wsgi_app
    response = self.full_dispatch_request()
  File "/usr/lib/python3/dist-packages/flask/app.py", line 1815, in full_dispatch_request
    rv = self.handle_user_exception(e)
  File "/usr/lib/python3/dist-packages/flask/app.py", line 1718, in handle_user_exception
    reraise(exc_type, exc_value, tb)
  File "/usr/lib/python3/dist-packages/flask/_compat.py", line 35, in reraise
    raise value
  File "/usr/lib/python3/dist-packages/flask/app.py", line 1813, in full_dispatch_request
    rv = self.dispatch_request()
  File "/usr/lib/python3/dist-packages/flask/app.py", line 1799, in dispatch_request
    return self.view_functions[rule.endpoint](**req.view_args)
  File "/home/orillion/CODING/HTBAH_Character_Creator/app/main/routes.py", line 40, in index
    events = db.session.query(db_event).all()
NameError: name 'db_event' is not defined
2019-10-15 18:00:08,009 INFO: Microblog startup [in /home/orillion/CODING/HTBAH_Character_Creator/app/__init__.py:84]
2019-10-15 18:00:11,072 ERROR: Exception on / [GET] [in /home/orillion/CODING/HTBAH_Character_Creator/venv/lib/python3.7/site-packages/flask/app.py:1891]
Traceback (most recent call last):
  File "/home/orillion/CODING/HTBAH_Character_Creator/venv/lib/python3.7/site-packages/flask/app.py", line 2446, in wsgi_app
    response = self.full_dispatch_request()
  File "/home/orillion/CODING/HTBAH_Character_Creator/venv/lib/python3.7/site-packages/flask/app.py", line 1951, in full_dispatch_request
    rv = self.handle_user_exception(e)
  File "/home/orillion/CODING/HTBAH_Character_Creator/venv/lib/python3.7/site-packages/flask/app.py", line 1820, in handle_user_exception
    reraise(exc_type, exc_value, tb)
  File "/home/orillion/CODING/HTBAH_Character_Creator/venv/lib/python3.7/site-packages/flask/_compat.py", line 39, in reraise
    raise value
  File "/home/orillion/CODING/HTBAH_Character_Creator/venv/lib/python3.7/site-packages/flask/app.py", line 1949, in full_dispatch_request
    rv = self.dispatch_request()
  File "/home/orillion/CODING/HTBAH_Character_Creator/venv/lib/python3.7/site-packages/flask/app.py", line 1935, in dispatch_request
    return self.view_functions[rule.endpoint](**req.view_args)
  File "/home/orillion/CODING/HTBAH_Character_Creator/app/main/routes.py", line 40, in index
    events = db.session.query(db_event).all()
NameError: name 'db_event' is not defined
2019-10-15 18:00:20,845 ERROR: Exception on /creator/create [GET] [in /home/orillion/CODING/HTBAH_Character_Creator/venv/lib/python3.7/site-packages/flask/app.py:1891]
Traceback (most recent call last):
  File "/home/orillion/CODING/HTBAH_Character_Creator/venv/lib/python3.7/site-packages/flask/app.py", line 2446, in wsgi_app
    response = self.full_dispatch_request()
  File "/home/orillion/CODING/HTBAH_Character_Creator/venv/lib/python3.7/site-packages/flask/app.py", line 1951, in full_dispatch_request
    rv = self.handle_user_exception(e)
  File "/home/orillion/CODING/HTBAH_Character_Creator/venv/lib/python3.7/site-packages/flask/app.py", line 1820, in handle_user_exception
    reraise(exc_type, exc_value, tb)
  File "/home/orillion/CODING/HTBAH_Character_Creator/venv/lib/python3.7/site-packages/flask/_compat.py", line 39, in reraise
    raise value
  File "/home/orillion/CODING/HTBAH_Character_Creator/venv/lib/python3.7/site-packages/flask/app.py", line 1949, in full_dispatch_request
    rv = self.dispatch_request()
  File "/home/orillion/CODING/HTBAH_Character_Creator/venv/lib/python3.7/site-packages/flask/app.py", line 1935, in dispatch_request
    return self.view_functions[rule.endpoint](**req.view_args)
  File "/home/orillion/CODING/HTBAH_Character_Creator/app/creator/routes.py", line 32, in creator_create
    form = LoginForm()
NameError: name 'LoginForm' is not defined
